Workbook

Sheet Historical Data
B1: Cisco Systems | E1: NVIDIA | H1: Rolls-Royce | K1: Loydes Bank | N1: BP | Q1: Procter and Gamble
B2: =IFERROR(__xludf.DUMMYFUNCTION("GOOGLEFINANCE(""CSCO"",""Price"",DATE(2021,1,1),TODAY(),""daily"")"),"Date") -> Date | C2: =IFERROR(__xludf.DUMMYFUNCTION("""COMPUTED_VALUE"""),"Close") -> Close | E2: =IFERROR(__xludf.DUMMYFUNCTION("GOOGLEFINANCE(""NVA"",""Price"",DATE(2021,1,1),TODAY(),""daily"")"),"Date") -> Date | F2: =IFERROR(__xludf.DUMMYFUNCTION("""COMPUTED_VALUE"""),"Close") -> Close | H2: =IFERROR(__xludf.DUMMYFUNCTION("GOOGLEFINANCE(""RR"",""Price"",DATE(2021,1,1),TODAY(),""daily"")"),"Date") -> Date | I2: =IFERROR(__xludf.DUMMYFUNCTION("""COMPUTED_VALUE"""),"Close") -> Close | K2: =IFERROR(__xludf.DUMMYFUNCTION("GOOGLEFINANCE(""LLOY"",""Price"",DATE(2021,1,1),TODAY(),""daily"")"),"Date") -> Date | L2: =IFERROR(__xludf.DUMMYFUNCTION("""COMPUTED_VALUE"""),"Close") -> Close | N2: =IFERROR(__xludf.DUMMYFUNCTION("GOOGLEFINANCE(""BP"",""Price"",DATE(2021,1,1),TODAY(),""daily"")"),"Date") -> Date | O2: =IFERROR(__xludf.DUMMYFUNCTION("""COMPUTED_VALUE"""),"Close") -> Close | Q2: =IFERROR(__xludf.DUMMYFUNCTION("GOOGLEFINANCE(""PG"",""Price"",DATE(2021,1,1),TODAY(),""daily"")"),"Date") -> Date | R2: =IFERROR(__xludf.DUMMYFUNCTION("""COMPUTED_VALUE"""),"Close") -> Close
B3: =IFERROR(__xludf.DUMMYFUNCTION("""COMPUTED_VALUE"""),44200.66666666667) -> 44200.667 | C3: =IFERROR(__xludf.DUMMYFUNCTION("""COMPUTED_VALUE"""),43.96) -> 43.96 | E3: =IFERROR(__xludf.DUMMYFUNCTION("""COMPUTED_VALUE"""),45497.66666666667) -> 45497.667 | F3: =IFERROR(__xludf.DUMMYFUNCTION("""COMPUTED_VALUE"""),0.96) -> 0.96 | H3: =IFERROR(__xludf.DUMMYFUNCTION("""COMPUTED_VALUE"""),45247.66666666667) -> 45247.667 | I3: =IFERROR(__xludf.DUMMYFUNCTION("""COMPUTED_VALUE"""),5.25) -> 5.25 | K3: =IFERROR(__xludf.DUMMYFUNCTION("""COMPUTED_VALUE"""),44200.6875) -> 44200.688 | L3: =IFERROR(__xludf.DUMMYFUNCTION("""COMPUTED_VALUE"""),34.84) -> 34.84 | N3: =IFERROR(__xludf.DUMMYFUNCTION("""COMPUTED_VALUE"""),44200.66666666667) -> 44200.667 | O3: =IFERROR(__xludf.DUMMYFUNCTION("""COMPUTED_VALUE"""),20.83) -> 20.83 | Q3: =IFERROR(__xludf.DUMMYFUNCTION("""COMPUTED_VALUE"""),44200.66666666667) -> 44200.667 | R3: =IFERROR(__xludf.DUMMYFUNCTION("""COMPUTED_VALUE"""),137.82) -> 137.82
B4: =IFERROR(__xludf.DUMMYFUNCTION("""COMPUTED_VALUE"""),44201.66666666667) -> 44201.667 | C4: =IFERROR(__xludf.DUMMYFUNCTION("""COMPUTED_VALUE"""),43.98) -> 43.98 | E4: =IFERROR(__xludf.DUMMYFUNCTION("""COMPUTED_VALUE"""),45498.66666666667) -> 45498.667 | F4: =IFERROR(__xludf.DUMMYFUNCTION("""COMPUTED_VALUE"""),0.96) -> 0.96 | H4: =IFERROR(__xludf.DUMMYFUNCTION("""COMPUTED_VALUE"""),45250.66666666667) -> 45250.667 | I4: =IFERROR(__xludf.DUMMYFUNCTION("""COMPUTED_VALUE"""),5.66) -> 5.66 | K4: =IFERROR(__xludf.DUMMYFUNCTION("""COMPUTED_VALUE"""),44201.6875) -> 44201.688 | L4: =IFERROR(__xludf.DUMMYFUNCTION("""COMPUTED_VALUE"""),35.21) -> 35.21 | N4: =IFERROR(__xludf.DUMMYFUNCTION("""COMPUTED_VALUE"""),44201.66666666667) -> 44201.667 | O4: =IFERROR(__xludf.DUMMYFUNCTION("""COMPUTED_VALUE"""),22.38) -> 22.38 | Q4: =IFERROR(__xludf.DUMMYFUNCTION("""COMPUTED_VALUE"""),44201.66666666667) -> 44201.667 | R4: =IFERROR(__xludf.DUMMYFUNCTION("""COMPUTED_VALUE"""),138.7) -> 138.7
B5: =IFERROR(__xludf.DUMMYFUNCTION("""COMPUTED_VALUE"""),44202.66666666667) -> 44202.667 | C5: =IFERROR(__xludf.DUMMYFUNCTION("""COMPUTED_VALUE"""),44.4) -> 44.4 | E5: =IFERROR(__xludf.DUMMYFUNCTION("""COMPUTED_VALUE"""),45499.66666666667) -> 45499.667 | F5: =IFERROR(__xludf.DUMMYFUNCTION("""COMPUTED_VALUE"""),1.0) -> 1 | H5: =IFERROR(__xludf.DUMMYFUNCTION("""COMPUTED_VALUE"""),45251.66666666667) -> 45251.667 | I5: =IFERROR(__xludf.DUMMYFUNCTION("""COMPUTED_VALUE"""),5.55) -> 5.55 | K5: =IFERROR(__xludf.DUMMYFUNCTION("""COMPUTED_VALUE"""),44202.6875) -> 44202.688 | L5: =IFERROR(__xludf.DUMMYFUNCTION("""COMPUTED_VALUE"""),37.16) -> 37.16 | N5: =IFERROR(__xludf.DUMMYFUNCTION("""COMPUTED_VALUE"""),44202.66666666667) -> 44202.667 | O5: =IFERROR(__xludf.DUMMYFUNCTION("""COMPUTED_VALUE"""),23.41) -> 23.41 | Q5: =IFERROR(__xludf.DUMMYFUNCTION("""COMPUTED_VALUE"""),44202.66666666667) -> 44202.667 | R5: =IFERROR(__xludf.DUMMYFUNCTION("""COMPUTED_VALUE"""),140.16) -> 140.16
B6: =IFERROR(__xludf.DUMMYFUNCTION("""COMPUTED_VALUE"""),44203.66666666667) -> 44203.667 | C6: =IFERROR(__xludf.DUMMYFUNCTION("""COMPUTED_VALUE"""),44.96) -> 44.96 | E6: =IFERROR(__xludf.DUMMYFUNCTION("""COMPUTED_VALUE"""),45502.66666666667) -> 45502.667 | F6: =IFERROR(__xludf.DUMMYFUNCTION("""COMPUTED_VALUE"""),1.01) -> 1.01 | H6: =IFERROR(__xludf.DUMMYFUNCTION("""COMPUTED_VALUE"""),45252.66666666667) -> 45252.667 | I6: =IFERROR(__xludf.DUMMYFUNCTION("""COMPUTED_VALUE"""),5.21) -> 5.21 | K6: =IFERROR(__xludf.DUMMYFUNCTION("""COMPUTED_VALUE"""),44203.6875) -> 44203.688 | L6: =IFERROR(__xludf.DUMMYFUNCTION("""COMPUTED_VALUE"""),36.89) -> 36.89 | N6: =IFERROR(__xludf.DUMMYFUNCTION("""COMPUTED_VALUE"""),44203.66666666667) -> 44203.667 | O6: =IFERROR(__xludf.DUMMYFUNCTION("""COMPUTED_VALUE"""),23.91) -> 23.91 | Q6: =IFERROR(__xludf.DUMMYFUNCTION("""COMPUTED_VALUE"""),44203.66666666667) -> 44203.667 | R6: =IFERROR(__xludf.DUMMYFUNCTION("""COMPUTED_VALUE"""),138.85) -> 138.85
B7: =IFERROR(__xludf.DUMMYFUNCTION("""COMPUTED_VALUE"""),44204.66666666667) -> 44204.667 | C7: =IFERROR(__xludf.DUMMYFUNCTION("""COMPUTED_VALUE"""),45.06) -> 45.06 | E7: =IFERROR(__xludf.DUMMYFUNCTION("""COMPUTED_VALUE"""),45504.66666666667) -> 45504.667 | F7: =IFERROR(__xludf.DUMMYFUNCTION("""COMPUTED_VALUE"""),1.02) -> 1.02 | H7: =IFERROR(__xludf.DUMMYFUNCTION("""COMPUTED_VALUE"""),45254.54513888889) -> 45254.545 | I7: =IFERROR(__xludf.DUMMYFUNCTION("""COMPUTED_VALUE"""),4.62) -> 4.62 | K7: =IFERROR(__xludf.DUMMYFUNCTION("""COMPUTED_VALUE"""),44204.6875) -> 44204.688 | L7: =IFERROR(__xludf.DUMMYFUNCTION("""COMPUTED_VALUE"""),36.83) -> 36.83 | N7: =IFERROR(__xludf.DUMMYFUNCTION("""COMPUTED_VALUE"""),44204.66666666667) -> 44204.667 | O7: =IFERROR(__xludf.DUMMYFUNCTION("""COMPUTED_VALUE"""),24.4) -> 24.4 | Q7: =IFERROR(__xludf.DUMMYFUNCTION("""COMPUTED_VALUE"""),44204.66666666667) -> 44204.667 | R7: =IFERROR(__xludf.DUMMYFUNCTION("""COMPUTED_VALUE"""),138.79) -> 138.79
B8: =IFERROR(__xludf.DUMMYFUNCTION("""COMPUTED_VALUE"""),44207.66666666667) -> 44207.667 | C8: =IFERROR(__xludf.DUMMYFUNCTION("""COMPUTED_VALUE"""),45.36) -> 45.36 | E8: =IFERROR(__xludf.DUMMYFUNCTION("""COMPUTED_VALUE"""),45505.66666666667) -> 45505.667 | F8: =IFERROR(__xludf.DUMMYFUNCTION("""COMPUTED_VALUE"""),1.03) -> 1.03 | H8: =IFERROR(__xludf.DUMMYFUNCTION("""COMPUTED_VALUE"""),45257.66666666667) -> 45257.667 | I8: =IFERROR(__xludf.DUMMYFUNCTION("""COMPUTED_VALUE"""),4.56) -> 4.56 | K8: =IFERROR(__xludf.DUMMYFUNCTION("""COMPUTED_VALUE"""),44207.6875) -> 44207.688 | L8: =IFERROR(__xludf.DUMMYFUNCTION("""COMPUTED_VALUE"""),36.17) -> 36.17 | N8: =IFERROR(__xludf.DUMMYFUNCTION("""COMPUTED_VALUE"""),44207.66666666667) -> 44207.667 | O8: =IFERROR(__xludf.DUMMYFUNCTION("""COMPUTED_VALUE"""),24.38) -> 24.38 | Q8: =IFERROR(__xludf.DUMMYFUNCTION("""COMPUTED_VALUE"""),44207.66666666667) -> 44207.667 | R8: =IFERROR(__xludf.DUMMYFUNCTION("""COMPUTED_VALUE"""),137.85) -> 137.85
B9: =IFERROR(__xludf.DUMMYFUNCTION("""COMPUTED_VALUE"""),44208.66666666667) -> 44208.667 | C9: =IFERROR(__xludf.DUMMYFUNCTION("""COMPUTED_VALUE"""),45.79) -> 45.79 | E9: =IFERROR(__xludf.DUMMYFUNCTION("""COMPUTED_VALUE"""),45506.66666666667) -> 45506.667 | F9: =IFERROR(__xludf.DUMMYFUNCTION("""COMPUTED_VALUE"""),1.02) -> 1.02 | H9: =IFERROR(__xludf.DUMMYFUNCTION("""COMPUTED_VALUE"""),45258.66666666667) -> 45258.667 | I9: =IFERROR(__xludf.DUMMYFUNCTION("""COMPUTED_VALUE"""),4.66) -> 4.66 | K9: =IFERROR(__xludf.DUMMYFUNCTION("""COMPUTED_VALUE"""),44208.6875) -> 44208.688 | L9: =IFERROR(__xludf.DUMMYFUNCTION("""COMPUTED_VALUE"""),36.74) -> 36.74 | N9: =IFERROR(__xludf.DUMMYFUNCTION("""COMPUTED_VALUE"""),44208.66666666667) -> 44208.667 | O9: =IFERROR(__xludf.DUMMYFUNCTION("""COMPUTED_VALUE"""),25.01) -> 25.01 | Q9: =IFERROR(__xludf.DUMMYFUNCTION("""COMPUTED_VALUE"""),44208.66666666667) -> 44208.667 | R9: =IFERROR(__xludf.DUMMYFUNCTION("""COMPUTED_VALUE"""),137.05) -> 137.05
B10: =IFERROR(__xludf.DUMMYFUNCTION("""COMPUTED_VALUE"""),44209.66666666667) -> 44209.667 | C10: =IFERROR(__xludf.DUMMYFUNCTION("""COMPUTED_VALUE"""),45.36) -> 45.36 | E10: =IFERROR(__xludf.DUMMYFUNCTION("""COMPUTED_VALUE"""),45509.66666666667) -> 45509.667 | F10: =IFERROR(__xludf.DUMMYFUNCTION("""COMPUTED_VALUE"""),0.99) -> 0.99 | H10: =IFERROR(__xludf.DUMMYFUNCTION("""COMPUTED_VALUE"""),45259.66666666667) -> 45259.667 | I10: =IFERROR(__xludf.DUMMYFUNCTION("""COMPUTED_VALUE"""),4.19) -> 4.19 | K10: =IFERROR(__xludf.DUMMYFUNCTION("""COMPUTED_VALUE"""),44209.6875) -> 44209.688 | L10: =IFERROR(__xludf.DUMMYFUNCTION("""COMPUTED_VALUE"""),36.24) -> 36.24 | N10: =IFERROR(__xludf.DUMMYFUNCTION("""COMPUTED_VALUE"""),44209.66666666667) -> 44209.667 | O10: =IFERROR(__xludf.DUMMYFUNCTION("""COMPUTED_VALUE"""),24.78) -> 24.78 | Q10: =IFERROR(__xludf.DUMMYFUNCTION("""COMPUTED_VALUE"""),44209.66666666667) -> 44209.667 | R10: =IFERROR(__xludf.DUMMYFUNCTION("""COMPUTED_VALUE"""),137.26) -> 137.26
B11: =IFERROR(__xludf.DUMMYFUNCTION("""COMPUTED_VALUE"""),44210.66666666667) -> 44210.667 | C11: =IFERROR(__xludf.DUMMYFUNCTION("""COMPUTED_VALUE"""),45.15) -> 45.15 | E11: =IFERROR(__xludf.DUMMYFUNCTION("""COMPUTED_VALUE"""),45510.66666666667) -> 45510.667 | F11: =IFERROR(__xludf.DUMMYFUNCTION("""COMPUTED_VALUE"""),0.99) -> 0.99 | H11: =IFERROR(__xludf.DUMMYFUNCTION("""COMPUTED_VALUE"""),45260.66666666667) -> 45260.667 | I11: =IFERROR(__xludf.DUMMYFUNCTION("""COMPUTED_VALUE"""),4.27) -> 4.27 | K11: =IFERROR(__xludf.DUMMYFUNCTION("""COMPUTED_VALUE"""),44210.6875) -> 44210.688 | L11: =IFERROR(__xludf.DUMMYFUNCTION("""COMPUTED_VALUE"""),36.46) -> 36.46 | N11: =IFERROR(__xludf.DUMMYFUNCTION("""COMPUTED_VALUE"""),44210.66666666667) -> 44210.667 | O11: =IFERROR(__xludf.DUMMYFUNCTION("""COMPUTED_VALUE"""),25.47) -> 25.47 | Q11: =IFERROR(__xludf.DUMMYFUNCTION("""COMPUTED_VALUE"""),44210.66666666667) -> 44210.667 | R11: =IFERROR(__xludf.DUMMYFUNCTION("""COMPUTED_VALUE"""),135.8) -> 135.8
B12: =IFERROR(__xludf.DUMMYFUNCTION("""COMPUTED_VALUE"""),44211.66666666667) -> 44211.667 | C12: =IFERROR(__xludf.DUMMYFUNCTION("""COMPUTED_VALUE"""),45.43) -> 45.43 | E12: =IFERROR(__xludf.DUMMYFUNCTION("""COMPUTED_VALUE"""),45511.66666666667) -> 45511.667 | F12: =IFERROR(__xludf.DUMMYFUNCTION("""COMPUTED_VALUE"""),1.01) -> 1.01 | H12: =IFERROR(__xludf.DUMMYFUNCTION("""COMPUTED_VALUE"""),45261.66666666667) -> 45261.667 | I12: =IFERROR(__xludf.DUMMYFUNCTION("""COMPUTED_VALUE"""),4.48) -> 4.48 | K12: =IFERROR(__xludf.DUMMYFUNCTION("""COMPUTED_VALUE"""),44211.6875) -> 44211.688 | L12: =IFERROR(__xludf.DUMMYFUNCTION("""COMPUTED_VALUE"""),35.94) -> 35.94 | N12: =IFERROR(__xludf.DUMMYFUNCTION("""COMPUTED_VALUE"""),44211.66666666667) -> 44211.667 | O12: =IFERROR(__xludf.DUMMYFUNCTION("""COMPUTED_VALUE"""),24.26) -> 24.26 | Q12: =IFERROR(__xludf.DUMMYFUNCTION("""COMPUTED_VALUE"""),44211.66666666667) -> 44211.667 | R12: =IFERROR(__xludf.DUMMYFUNCTION("""COMPUTED_VALUE"""),134.78) -> 134.78
B13: =IFERROR(__xludf.DUMMYFUNCTION("""COMPUTED_VALUE"""),44215.66666666667) -> 44215.667 | C13: =IFERROR(__xludf.DUMMYFUNCTION("""COMPUTED_VALUE"""),45.19) -> 45.19 | E13: =IFERROR(__xludf.DUMMYFUNCTION("""COMPUTED_VALUE"""),45512.66666666667) -> 45512.667 | F13: =IFERROR(__xludf.DUMMYFUNCTION("""COMPUTED_VALUE"""),1.01) -> 1.01 | H13: =IFERROR(__xludf.DUMMYFUNCTION("""COMPUTED_VALUE"""),45264.66666666667) -> 45264.667 | I13: =IFERROR(__xludf.DUMMYFUNCTION("""COMPUTED_VALUE"""),5.03) -> 5.03 | K13: =IFERROR(__xludf.DUMMYFUNCTION("""COMPUTED_VALUE"""),44214.6875) -> 44214.688 | L13: =IFERROR(__xludf.DUMMYFUNCTION("""COMPUTED_VALUE"""),36.17) -> 36.17 | N13: =IFERROR(__xludf.DUMMYFUNCTION("""COMPUTED_VALUE"""),44215.66666666667) -> 44215.667 | O13: =IFERROR(__xludf.DUMMYFUNCTION("""COMPUTED_VALUE"""),24.65) -> 24.65 | Q13: =IFERROR(__xludf.DUMMYFUNCTION("""COMPUTED_VALUE"""),44215.66666666667) -> 44215.667 | R13: =IFERROR(__xludf.DUMMYFUNCTION("""COMPUTED_VALUE"""),133.6) -> 133.6
B14: =IFERROR(__xludf.DUMMYFUNCTION("""COMPUTED_VALUE"""),44216.66666666667) -> 44216.667 | C14: =IFERROR(__xludf.DUMMYFUNCTION("""COMPUTED_VALUE"""),45.34) -> 45.34 | E14: =IFERROR(__xludf.DUMMYFUNCTION("""COMPUTED_VALUE"""),45513.66666666667) -> 45513.667 | F14: =IFERROR(__xludf.DUMMYFUNCTION("""COMPUTED_VALUE"""),1.14) -> 1.14 | H14: =IFERROR(__xludf.DUMMYFUNCTION("""COMPUTED_VALUE"""),45265.66666666667) -> 45265.667 | I14: =IFERROR(__xludf.DUMMYFUNCTION("""COMPUTED_VALUE"""),4.97) -> 4.97 | K14: =IFERROR(__xludf.DUMMYFUNCTION("""COMPUTED_VALUE"""),44215.6875) -> 44215.688 | L14: =IFERROR(__xludf.DUMMYFUNCTION("""COMPUTED_VALUE"""),36.0) -> 36 | N14: =IFERROR(__xludf.DUMMYFUNCTION("""COMPUTED_VALUE"""),44216.66666666667) -> 44216.667 | O14: =IFERROR(__xludf.DUMMYFUNCTION("""COMPUTED_VALUE"""),24.81) -> 24.81 | Q14: =IFERROR(__xludf.DUMMYFUNCTION("""COMPUTED_VALUE"""),44216.66666666667) -> 44216.667 | R14: =IFERROR(__xludf.DUMMYFUNCTION("""COMPUTED_VALUE"""),131.93) -> 131.93
B15: =IFERROR(__xludf.DUMMYFUNCTION("""COMPUTED_VALUE"""),44217.66666666667) -> 44217.667 | C15: =IFERROR(__xludf.DUMMYFUNCTION("""COMPUTED_VALUE"""),45.11) -> 45.11 | E15: =IFERROR(__xludf.DUMMYFUNCTION("""COMPUTED_VALUE"""),45516.66666666667) -> 45516.667 | F15: =IFERROR(__xludf.DUMMYFUNCTION("""COMPUTED_VALUE"""),1.15) -> 1.15 | H15: =IFERROR(__xludf.DUMMYFUNCTION("""COMPUTED_VALUE"""),45266.66666666667) -> 45266.667 | I15: =IFERROR(__xludf.DUMMYFUNCTION("""COMPUTED_VALUE"""),5.09) -> 5.09 | K15: =IFERROR(__xludf.DUMMYFUNCTION("""COMPUTED_VALUE"""),44216.6875) -> 44216.688 | L15: =IFERROR(__xludf.DUMMYFUNCTION("""COMPUTED_VALUE"""),35.78) -> 35.78 | N15: =IFERROR(__xludf.DUMMYFUNCTION("""COMPUTED_VALUE"""),44217.66666666667) -> 44217.667 | O15: =IFERROR(__xludf.DUMMYFUNCTION("""COMPUTED_VALUE"""),24.02) -> 24.02 | Q15: =IFERROR(__xludf.DUMMYFUNCTION("""COMPUTED_VALUE"""),44217.66666666667) -> 44217.667 | R15: =IFERROR(__xludf.DUMMYFUNCTION("""COMPUTED_VALUE"""),131.01) -> 131.01
B16: =IFERROR(__xludf.DUMMYFUNCTION("""COMPUTED_VALUE"""),44218.66666666667) -> 44218.667 | C16: =IFERROR(__xludf.DUMMYFUNCTION("""COMPUTED_VALUE"""),44.77) -> 44.77 | E16: =IFERROR(__xludf.DUMMYFUNCTION("""COMPUTED_VALUE"""),45517.66666666667) -> 45517.667 | F16: =IFERROR(__xludf.DUMMYFUNCTION("""COMPUTED_VALUE"""),1.0) -> 1 | H16: =IFERROR(__xludf.DUMMYFUNCTION("""COMPUTED_VALUE"""),45267.66666666667) -> 45267.667 | I16: =IFERROR(__xludf.DUMMYFUNCTION("""COMPUTED_VALUE"""),5.11) -> 5.11 | K16: =IFERROR(__xludf.DUMMYFUNCTION("""COMPUTED_VALUE"""),44217.6875) -> 44217.688 | L16: =IFERROR(__xludf.DUMMYFUNCTION("""COMPUTED_VALUE"""),35.32) -> 35.32 | N16: =IFERROR(__xludf.DUMMYFUNCTION("""COMPUTED_VALUE"""),44218.66666666667) -> 44218.667 | O16: =IFERROR(__xludf.DUMMYFUNCTION("""COMPUTED_VALUE"""),23.87) -> 23.87 | Q16: =IFERROR(__xludf.DUMMYFUNCTION("""COMPUTED_VALUE"""),44218.66666666667) -> 44218.667 | R16: =IFERROR(__xludf.DUMMYFUNCTION("""COMPUTED_VALUE"""),130.0) -> 130
B17: =IFERROR(__xludf.DUMMYFUNCTION("""COMPUTED_VALUE"""),44221.66666666667) -> 44221.667 | C17: =IFERROR(__xludf.DUMMYFUNCTION("""COMPUTED_VALUE"""),45.03) -> 45.03 | E17: =IFERROR(__xludf.DUMMYFUNCTION("""COMPUTED_VALUE"""),45518.66666666667) -> 45518.667 | F17: =IFERROR(__xludf.DUMMYFUNCTION("""COMPUTED_VALUE"""),0.97) -> 0.97 | H17: =IFERROR(__xludf.DUMMYFUNCTION("""COMPUTED_VALUE"""),45268.66666666667) -> 45268.667 | I17: =IFERROR(__xludf.DUMMYFUNCTION("""COMPUTED_VALUE"""),5.01) -> 5.01 | K17: =IFERROR(__xludf.DUMMYFUNCTION("""COMPUTED_VALUE"""),44218.6875) -> 44218.688 | L17: =IFERROR(__xludf.DUMMYFUNCTION("""COMPUTED_VALUE"""),34.77) -> 34.77 | N17: =IFERROR(__xludf.DUMMYFUNCTION("""COMPUTED_VALUE"""),44221.66666666667) -> 44221.667 | O17: =IFERROR(__xludf.DUMMYFUNCTION("""COMPUTED_VALUE"""),23.07) -> 23.07 | Q17: =IFERROR(__xludf.DUMMYFUNCTION("""COMPUTED_VALUE"""),44221.66666666667) -> 44221.667 | R17: =IFERROR(__xludf.DUMMYFUNCTION("""COMPUTED_VALUE"""),132.24) -> 132.24
B18: =IFERROR(__xludf.DUMMYFUNCTION("""COMPUTED_VALUE"""),44222.66666666667) -> 44222.667 | C18: =IFERROR(__xludf.DUMMYFUNCTION("""COMPUTED_VALUE"""),45.26) -> 45.26 | E18: =IFERROR(__xludf.DUMMYFUNCTION("""COMPUTED_VALUE"""),45519.66666666667) -> 45519.667 | F18: =IFERROR(__xludf.DUMMYFUNCTION("""COMPUTED_VALUE"""),0.94) -> 0.94 | H18: =IFERROR(__xludf.DUMMYFUNCTION("""COMPUTED_VALUE"""),45271.66666666667) -> 45271.667 | I18: =IFERROR(__xludf.DUMMYFUNCTION("""COMPUTED_VALUE"""),4.98) -> 4.98 | K18: =IFERROR(__xludf.DUMMYFUNCTION("""COMPUTED_VALUE"""),44221.6875) -> 44221.688 | L18: =IFERROR(__xludf.DUMMYFUNCTION("""COMPUTED_VALUE"""),33.84) -> 33.84 | N18: =IFERROR(__xludf.DUMMYFUNCTION("""COMPUTED_VALUE"""),44222.66666666667) -> 44222.667 | O18: =IFERROR(__xludf.DUMMYFUNCTION("""COMPUTED_VALUE"""),23.03) -> 23.03 | Q18: =IFERROR(__xludf.DUMMYFUNCTION("""COMPUTED_VALUE"""),44222.66666666667) -> 44222.667 | R18: =IFERROR(__xludf.DUMMYFUNCTION("""COMPUTED_VALUE"""),133.09) -> 133.09
B19: =IFERROR(__xludf.DUMMYFUNCTION("""COMPUTED_VALUE"""),44223.66666666667) -> 44223.667 | C19: =IFERROR(__xludf.DUMMYFUNCTION("""COMPUTED_VALUE"""),45.7) -> 45.7 | E19: =IFERROR(__xludf.DUMMYFUNCTION("""COMPUTED_VALUE"""),45520.66666666667) -> 45520.667 | F19: =IFERROR(__xludf.DUMMYFUNCTION("""COMPUTED_VALUE"""),1.07) -> 1.07 | H19: =IFERROR(__xludf.DUMMYFUNCTION("""COMPUTED_VALUE"""),45272.66666666667) -> 45272.667 | I19: =IFERROR(__xludf.DUMMYFUNCTION("""COMPUTED_VALUE"""),4.78) -> 4.78 | K19: =IFERROR(__xludf.DUMMYFUNCTION("""COMPUTED_VALUE"""),44222.6875) -> 44222.688 | L19: =IFERROR(__xludf.DUMMYFUNCTION("""COMPUTED_VALUE"""),34.41) -> 34.41 | N19: =IFERROR(__xludf.DUMMYFUNCTION("""COMPUTED_VALUE"""),44223.66666666667) -> 44223.667 | O19: =IFERROR(__xludf.DUMMYFUNCTION("""COMPUTED_VALUE"""),22.73) -> 22.73 | Q19: =IFERROR(__xludf.DUMMYFUNCTION("""COMPUTED_VALUE"""),44223.66666666667) -> 44223.667 | R19: =IFERROR(__xludf.DUMMYFUNCTION("""COMPUTED_VALUE"""),128.38) -> 128.38
B20: =IFERROR(__xludf.DUMMYFUNCTION("""COMPUTED_VALUE"""),44224.66666666667) -> 44224.667 | C20: =IFERROR(__xludf.DUMMYFUNCTION("""COMPUTED_VALUE"""),45.34) -> 45.34 | E20: =IFERROR(__xludf.DUMMYFUNCTION("""COMPUTED_VALUE"""),45523.66666666667) -> 45523.667 | F20: =IFERROR(__xludf.DUMMYFUNCTION("""COMPUTED_VALUE"""),1.17) -> 1.17 | H20: =IFERROR(__xludf.DUMMYFUNCTION("""COMPUTED_VALUE"""),45273.66666666667) -> 45273.667 | I20: =IFERROR(__xludf.DUMMYFUNCTION("""COMPUTED_VALUE"""),4.8) -> 4.8 | K20: =IFERROR(__xludf.DUMMYFUNCTION("""COMPUTED_VALUE"""),44223.6875) -> 44223.688 | L20: =IFERROR(__xludf.DUMMYFUNCTION("""COMPUTED_VALUE"""),33.25) -> 33.25 | N20: =IFERROR(__xludf.DUMMYFUNCTION("""COMPUTED_VALUE"""),44224.66666666667) -> 44224.667 | O20: =IFERROR(__xludf.DUMMYFUNCTION("""COMPUTED_VALUE"""),22.86) -> 22.86 | Q20: =IFERROR(__xludf.DUMMYFUNCTION("""COMPUTED_VALUE"""),44224.66666666667) -> 44224.667 | R20: =IFERROR(__xludf.DUMMYFUNCTION("""COMPUTED_VALUE"""),130.36) -> 130.36
B21: =IFERROR(__xludf.DUMMYFUNCTION("""COMPUTED_VALUE"""),44225.66666666667) -> 44225.667 | C21: =IFERROR(__xludf.DUMMYFUNCTION("""COMPUTED_VALUE"""),44.58) -> 44.58 | E21: =IFERROR(__xludf.DUMMYFUNCTION("""COMPUTED_VALUE"""),45524.66666666667) -> 45524.667 | F21: =IFERROR(__xludf.DUMMYFUNCTION("""COMPUTED_VALUE"""),1.17) -> 1.17 | H21: =IFERROR(__xludf.DUMMYFUNCTION("""COMPUTED_VALUE"""),45274.66666666667) -> 45274.667 | I21: =IFERROR(__xludf.DUMMYFUNCTION("""COMPUTED_VALUE"""),4.73) -> 4.73 | K21: =IFERROR(__xludf.DUMMYFUNCTION("""COMPUTED_VALUE"""),44224.6875) -> 44224.688 | L21: =IFERROR(__xludf.DUMMYFUNCTION("""COMPUTED_VALUE"""),33.47) -> 33.47 | N21: =IFERROR(__xludf.DUMMYFUNCTION("""COMPUTED_VALUE"""),44225.66666666667) -> 44225.667 | O21: =IFERROR(__xludf.DUMMYFUNCTION("""COMPUTED_VALUE"""),22.22) -> 22.22 | Q21: =IFERROR(__xludf.DUMMYFUNCTION("""COMPUTED_VALUE"""),44225.66666666667) -> 44225.667 | R21: =IFERROR(__xludf.DUMMYFUNCTION("""COMPUTED_VALUE"""),128.21) -> 128.21
B22: =IFERROR(__xludf.DUMMYFUNCTION("""COMPUTED_VALUE"""),44228.66666666667) -> 44228.667 | C22: =IFERROR(__xludf.DUMMYFUNCTION("""COMPUTED_VALUE"""),45.4) -> 45.4 | E22: =IFERROR(__xludf.DUMMYFUNCTION("""COMPUTED_VALUE"""),45525.66666666667) -> 45525.667 | F22: =IFERROR(__xludf.DUMMYFUNCTION("""COMPUTED_VALUE"""),1.18) -> 1.18 | H22: =IFERROR(__xludf.DUMMYFUNCTION("""COMPUTED_VALUE"""),45275.66666666667) -> 45275.667 | I22: =IFERROR(__xludf.DUMMYFUNCTION("""COMPUTED_VALUE"""),4.71) -> 4.71 | K22: =IFERROR(__xludf.DUMMYFUNCTION("""COMPUTED_VALUE"""),44225.6875) -> 44225.688 | L22: =IFERROR(__xludf.DUMMYFUNCTION("""COMPUTED_VALUE"""),33.0) -> 33 | N22: =IFERROR(__xludf.DUMMYFUNCTION("""COMPUTED_VALUE"""),44228.66666666667) -> 44228.667 | O22: =IFERROR(__xludf.DUMMYFUNCTION("""COMPUTED_VALUE"""),22.21) -> 22.21 | Q22: =IFERROR(__xludf.DUMMYFUNCTION("""COMPUTED_VALUE"""),44228.66666666667) -> 44228.667 | R22: =IFERROR(__xludf.DUMMYFUNCTION("""COMPUTED_VALUE"""),128.97) -> 128.97
B23: =IFERROR(__xludf.DUMMYFUNCTION("""COMPUTED_VALUE"""),44229.66666666667) -> 44229.667 | C23: =IFERROR(__xludf.DUMMYFUNCTION("""COMPUTED_VALUE"""),45.83) -> 45.83 | E23: =IFERROR(__xludf.DUMMYFUNCTION("""COMPUTED_VALUE"""),45526.66666666667) -> 45526.667 | F23: =IFERROR(__xludf.DUMMYFUNCTION("""COMPUTED_VALUE"""),1.18) -> 1.18 | H23: =IFERROR(__xludf.DUMMYFUNCTION("""COMPUTED_VALUE"""),45278.66666666667) -> 45278.667 | I23: =IFERROR(__xludf.DUMMYFUNCTION("""COMPUTED_VALUE"""),4.8) -> 4.8 | K23: =IFERROR(__xludf.DUMMYFUNCTION("""COMPUTED_VALUE"""),44228.6875) -> 44228.688 | L23: =IFERROR(__xludf.DUMMYFUNCTION("""COMPUTED_VALUE"""),33.53) -> 33.53 | N23: =IFERROR(__xludf.DUMMYFUNCTION("""COMPUTED_VALUE"""),44229.66666666667) -> 44229.667 | O23: =IFERROR(__xludf.DUMMYFUNCTION("""COMPUTED_VALUE"""),20.75) -> 20.75 | Q23: =IFERROR(__xludf.DUMMYFUNCTION("""COMPUTED_VALUE"""),44229.66666666667) -> 44229.667 | R23: =IFERROR(__xludf.DUMMYFUNCTION("""COMPUTED_VALUE"""),128.79) -> 128.79
B24: =IFERROR(__xludf.DUMMYFUNCTION("""COMPUTED_VALUE"""),44230.66666666667) -> 44230.667 | C24: =IFERROR(__xludf.DUMMYFUNCTION("""COMPUTED_VALUE"""),45.77) -> 45.77 | E24: =IFERROR(__xludf.DUMMYFUNCTION("""COMPUTED_VALUE"""),45527.66666666667) -> 45527.667 | F24: =IFERROR(__xludf.DUMMYFUNCTION("""COMPUTED_VALUE"""),1.24) -> 1.24 | H24: =IFERROR(__xludf.DUMMYFUNCTION("""COMPUTED_VALUE"""),45279.66666666667) -> 45279.667 | I24: =IFERROR(__xludf.DUMMYFUNCTION("""COMPUTED_VALUE"""),5.07) -> 5.07 | K24: =IFERROR(__xludf.DUMMYFUNCTION("""COMPUTED_VALUE"""),44229.6875) -> 44229.688 | L24: =IFERROR(__xludf.DUMMYFUNCTION("""COMPUTED_VALUE"""),33.99) -> 33.99 | N24: =IFERROR(__xludf.DUMMYFUNCTION("""COMPUTED_VALUE"""),44230.66666666667) -> 44230.667 | O24: =IFERROR(__xludf.DUMMYFUNCTION("""COMPUTED_VALUE"""),21.27) -> 21.27 | Q24: =IFERROR(__xludf.DUMMYFUNCTION("""COMPUTED_VALUE"""),44230.66666666667) -> 44230.667 | R24: =IFERROR(__xludf.DUMMYFUNCTION("""COMPUTED_VALUE"""),128.95) -> 128.95
B25: =IFERROR(__xludf.DUMMYFUNCTION("""COMPUTED_VALUE"""),44231.66666666667) -> 44231.667 | C25: =IFERROR(__xludf.DUMMYFUNCTION("""COMPUTED_VALUE"""),47.25) -> 47.25 | E25: =IFERROR(__xludf.DUMMYFUNCTION("""COMPUTED_VALUE"""),45530.66666666667) -> 45530.667 | F25: =IFERROR(__xludf.DUMMYFUNCTION("""COMPUTED_VALUE"""),1.21) -> 1.21 | H25: =IFERROR(__xludf.DUMMYFUNCTION("""COMPUTED_VALUE"""),45280.66666666667) -> 45280.667 | I25: =IFERROR(__xludf.DUMMYFUNCTION("""COMPUTED_VALUE"""),4.99) -> 4.99 | K25: =IFERROR(__xludf.DUMMYFUNCTION("""COMPUTED_VALUE"""),44230.6875) -> 44230.688 | L25: =IFERROR(__xludf.DUMMYFUNCTION("""COMPUTED_VALUE"""),34.18) -> 34.18 | N25: =IFERROR(__xludf.DUMMYFUNCTION("""COMPUTED_VALUE"""),44231.66666666667) -> 44231.667 | O25: =IFERROR(__xludf.DUMMYFUNCTION("""COMPUTED_VALUE"""),20.99) -> 20.99 | Q25: =IFERROR(__xludf.DUMMYFUNCTION("""COMPUTED_VALUE"""),44231.66666666667) -> 44231.667 | R25: =IFERROR(__xludf.DUMMYFUNCTION("""COMPUTED_VALUE"""),129.03) -> 129.03
B26: =IFERROR(__xludf.DUMMYFUNCTION("""COMPUTED_VALUE"""),44232.66666666667) -> 44232.667 | C26: =IFERROR(__xludf.DUMMYFUNCTION("""COMPUTED_VALUE"""),48.08) -> 48.08 | E26: =IFERROR(__xludf.DUMMYFUNCTION("""COMPUTED_VALUE"""),45531.66666666667) -> 45531.667 | F26: =IFERROR(__xludf.DUMMYFUNCTION("""COMPUTED_VALUE"""),1.23) -> 1.23 | H26: =IFERROR(__xludf.DUMMYFUNCTION("""COMPUTED_VALUE"""),45281.66666666667) -> 45281.667 | I26: =IFERROR(__xludf.DUMMYFUNCTION("""COMPUTED_VALUE"""),5.5) -> 5.5 | K26: =IFERROR(__xludf.DUMMYFUNCTION("""COMPUTED_VALUE"""),44231.6875) -> 44231.688 | L26: =IFERROR(__xludf.DUMMYFUNCTION("""COMPUTED_VALUE"""),36.11) -> 36.11 | N26: =IFERROR(__xludf.DUMMYFUNCTION("""COMPUTED_VALUE"""),44232.66666666667) -> 44232.667 | O26: =IFERROR(__xludf.DUMMYFUNCTION("""COMPUTED_VALUE"""),20.81) -> 20.81 | Q26: =IFERROR(__xludf.DUMMYFUNCTION("""COMPUTED_VALUE"""),44232.66666666667) -> 44232.667 | R26: =IFERROR(__xludf.DUMMYFUNCTION("""COMPUTED_VALUE"""),129.57) -> 129.57
B27: =IFERROR(__xludf.DUMMYFUNCTION("""COMPUTED_VALUE"""),44235.66666666667) -> 44235.667 | C27: =IFERROR(__xludf.DUMMYFUNCTION("""COMPUTED_VALUE"""),48.94) -> 48.94 | E27: =IFERROR(__xludf.DUMMYFUNCTION("""COMPUTED_VALUE"""),45532.66666666667) -> 45532.667 | F27: =IFERROR(__xludf.DUMMYFUNCTION("""COMPUTED_VALUE"""),1.2) -> 1.2 | H27: =IFERROR(__xludf.DUMMYFUNCTION("""COMPUTED_VALUE"""),45282.66666666667) -> 45282.667 | I27: =IFERROR(__xludf.DUMMYFUNCTION("""COMPUTED_VALUE"""),5.61) -> 5.61 | K27: =IFERROR(__xludf.DUMMYFUNCTION("""COMPUTED_VALUE"""),44232.6875) -> 44232.688 | L27: =IFERROR(__xludf.DUMMYFUNCTION("""COMPUTED_VALUE"""),37.0) -> 37 | N27: =IFERROR(__xludf.DUMMYFUNCTION("""COMPUTED_VALUE"""),44235.66666666667) -> 44235.667 | O27: =IFERROR(__xludf.DUMMYFUNCTION("""COMPUTED_VALUE"""),22.03) -> 22.03 | Q27: =IFERROR(__xludf.DUMMYFUNCTION("""COMPUTED_VALUE"""),44235.66666666667) -> 44235.667 | R27: =IFERROR(__xludf.DUMMYFUNCTION("""COMPUTED_VALUE"""),129.17) -> 129.17
B28: =IFERROR(__xludf.DUMMYFUNCTION("""COMPUTED_VALUE"""),44236.66666666667) -> 44236.667 | C28: =IFERROR(__xludf.DUMMYFUNCTION("""COMPUTED_VALUE"""),48.5) -> 48.5 | E28: =IFERROR(__xludf.DUMMYFUNCTION("""COMPUTED_VALUE"""),45533.66666666667) -> 45533.667 | F28: =IFERROR(__xludf.DUMMYFUNCTION("""COMPUTED_VALUE"""),1.26) -> 1.26 | H28: =IFERROR(__xludf.DUMMYFUNCTION("""COMPUTED_VALUE"""),45286.66666666667) -> 45286.667 | I28: =IFERROR(__xludf.DUMMYFUNCTION("""COMPUTED_VALUE"""),5.4) -> 5.4 | K28: =IFERROR(__xludf.DUMMYFUNCTION("""COMPUTED_VALUE"""),44235.6875) -> 44235.688 | L28: =IFERROR(__xludf.DUMMYFUNCTION("""COMPUTED_VALUE"""),37.7) -> 37.7 | N28: =IFERROR(__xludf.DUMMYFUNCTION("""COMPUTED_VALUE"""),44236.66666666667) -> 44236.667 | O28: =IFERROR(__xludf.DUMMYFUNCTION("""COMPUTED_VALUE"""),21.73) -> 21.73 | Q28: =IFERROR(__xludf.DUMMYFUNCTION("""COMPUTED_VALUE"""),44236.66666666667) -> 44236.667 | R28: =IFERROR(__xludf.DUMMYFUNCTION("""COMPUTED_VALUE"""),128.67) -> 128.67
B29: =IFERROR(__xludf.DUMMYFUNCTION("""COMPUTED_VALUE"""),44237.66666666667) -> 44237.667 | C29: =IFERROR(__xludf.DUMMYFUNCTION("""COMPUTED_VALUE"""),47.24) -> 47.24 | E29: =IFERROR(__xludf.DUMMYFUNCTION("""COMPUTED_VALUE"""),45534.66666666667) -> 45534.667 | F29: =IFERROR(__xludf.DUMMYFUNCTION("""COMPUTED_VALUE"""),1.22) -> 1.22 | H29: =IFERROR(__xludf.DUMMYFUNCTION("""COMPUTED_VALUE"""),45287.66666666667) -> 45287.667 | I29: =IFERROR(__xludf.DUMMYFUNCTION("""COMPUTED_VALUE"""),5.82) -> 5.82 | K29: =IFERROR(__xludf.DUMMYFUNCTION("""COMPUTED_VALUE"""),44236.6875) -> 44236.688 | L29: =IFERROR(__xludf.DUMMYFUNCTION("""COMPUTED_VALUE"""),37.55) -> 37.55 | N29: =IFERROR(__xludf.DUMMYFUNCTION("""COMPUTED_VALUE"""),44237.66666666667) -> 44237.667 | O29: =IFERROR(__xludf.DUMMYFUNCTION("""COMPUTED_VALUE"""),21.58) -> 21.58 | Q29: =IFERROR(__xludf.DUMMYFUNCTION("""COMPUTED_VALUE"""),44237.66666666667) -> 44237.667 | R29: =IFERROR(__xludf.DUMMYFUNCTION("""COMPUTED_VALUE"""),128.22) -> 128.22
B30: =IFERROR(__xludf.DUMMYFUNCTION("""COMPUTED_VALUE"""),44238.66666666667) -> 44238.667 | C30: =IFERROR(__xludf.DUMMYFUNCTION("""COMPUTED_VALUE"""),47.58) -> 47.58 | E30: =IFERROR(__xludf.DUMMYFUNCTION("""COMPUTED_VALUE"""),45538.66666666667) -> 45538.667 | F30: =IFERROR(__xludf.DUMMYFUNCTION("""COMPUTED_VALUE"""),1.11) -> 1.11 | H30: =IFERROR(__xludf.DUMMYFUNCTION("""COMPUTED_VALUE"""),45288.66666666667) -> 45288.667 | I30: =IFERROR(__xludf.DUMMYFUNCTION("""COMPUTED_VALUE"""),5.93) -> 5.93 | K30: =IFERROR(__xludf.DUMMYFUNCTION("""COMPUTED_VALUE"""),44237.6875) -> 44237.688 | L30: =IFERROR(__xludf.DUMMYFUNCTION("""COMPUTED_VALUE"""),37.5) -> 37.5 | N30: =IFERROR(__xludf.DUMMYFUNCTION("""COMPUTED_VALUE"""),44238.66666666667) -> 44238.667 | O30: =IFERROR(__xludf.DUMMYFUNCTION("""COMPUTED_VALUE"""),21.37) -> 21.37 | Q30: =IFERROR(__xludf.DUMMYFUNCTION("""COMPUTED_VALUE"""),44238.66666666667) -> 44238.667 | R30: =IFERROR(__xludf.DUMMYFUNCTION("""COMPUTED_VALUE"""),128.33) -> 128.33
B31: =IFERROR(__xludf.DUMMYFUNCTION("""COMPUTED_VALUE"""),44239.66666666667) -> 44239.667 | C31: =IFERROR(__xludf.DUMMYFUNCTION("""COMPUTED_VALUE"""),47.29) -> 47.29 | E31: =IFERROR(__xludf.DUMMYFUNCTION("""COMPUTED_VALUE"""),45539.66666666667) -> 45539.667 | F31: =IFERROR(__xludf.DUMMYFUNCTION("""COMPUTED_VALUE"""),1.16) -> 1.16 | H31: =IFERROR(__xludf.DUMMYFUNCTION("""COMPUTED_VALUE"""),45289.66666666667) -> 45289.667 | I31: =IFERROR(__xludf.DUMMYFUNCTION("""COMPUTED_VALUE"""),5.95) -> 5.95 | K31: =IFERROR(__xludf.DUMMYFUNCTION("""COMPUTED_VALUE"""),44238.6875) -> 44238.688 | L31: =IFERROR(__xludf.DUMMYFUNCTION("""COMPUTED_VALUE"""),37.07) -> 37.07 | N31: =IFERROR(__xludf.DUMMYFUNCTION("""COMPUTED_VALUE"""),44239.66666666667) -> 44239.667 | O31: =IFERROR(__xludf.DUMMYFUNCTION("""COMPUTED_VALUE"""),21.91) -> 21.91 | Q31: =IFERROR(__xludf.DUMMYFUNCTION("""COMPUTED_VALUE"""),44239.66666666667) -> 44239.667 | R31: =IFERROR(__xludf.DUMMYFUNCTION("""COMPUTED_VALUE"""),127.62) -> 127.62
B32: =IFERROR(__xludf.DUMMYFUNCTION("""COMPUTED_VALUE"""),44243.66666666667) -> 44243.667 | C32: =IFERROR(__xludf.DUMMYFUNCTION("""COMPUTED_VALUE"""),46.51) -> 46.51 | E32: =IFERROR(__xludf.DUMMYFUNCTION("""COMPUTED_VALUE"""),45540.66666666667) -> 45540.667 | F32: =IFERROR(__xludf.DUMMYFUNCTION("""COMPUTED_VALUE"""),1.2) -> 1.2 | H32: =IFERROR(__xludf.DUMMYFUNCTION("""COMPUTED_VALUE"""),45293.66666666667) -> 45293.667 | I32: =IFERROR(__xludf.DUMMYFUNCTION("""COMPUTED_VALUE"""),6.05) -> 6.05 | K32: =IFERROR(__xludf.DUMMYFUNCTION("""COMPUTED_VALUE"""),44239.6875) -> 44239.688 | L32: =IFERROR(__xludf.DUMMYFUNCTION("""COMPUTED_VALUE"""),37.1) -> 37.1 | N32: =IFERROR(__xludf.DUMMYFUNCTION("""COMPUTED_VALUE"""),44243.66666666667) -> 44243.667 | O32: =IFERROR(__xludf.DUMMYFUNCTION("""COMPUTED_VALUE"""),23.18) -> 23.18 | Q32: =IFERROR(__xludf.DUMMYFUNCTION("""COMPUTED_VALUE"""),44243.66666666667) -> 44243.667 | R32: =IFERROR(__xludf.DUMMYFUNCTION("""COMPUTED_VALUE"""),127.92) -> 127.92
B33: =IFERROR(__xludf.DUMMYFUNCTION("""COMPUTED_VALUE"""),44244.66666666667) -> 44244.667 | C33: =IFERROR(__xludf.DUMMYFUNCTION("""COMPUTED_VALUE"""),46.25) -> 46.25 | E33: =IFERROR(__xludf.DUMMYFUNCTION("""COMPUTED_VALUE"""),45541.66666666667) -> 45541.667 | F33: =IFERROR(__xludf.DUMMYFUNCTION("""COMPUTED_VALUE"""),1.2) -> 1.2 | H33: =IFERROR(__xludf.DUMMYFUNCTION("""COMPUTED_VALUE"""),45294.66666666667) -> 45294.667 | I33: =IFERROR(__xludf.DUMMYFUNCTION("""COMPUTED_VALUE"""),6.01) -> 6.01 | K33: =IFERROR(__xludf.DUMMYFUNCTION("""COMPUTED_VALUE"""),44242.6875) -> 44242.688 | L33: =IFERROR(__xludf.DUMMYFUNCTION("""COMPUTED_VALUE"""),39.09) -> 39.09 | N33: =IFERROR(__xludf.DUMMYFUNCTION("""COMPUTED_VALUE"""),44244.66666666667) -> 44244.667 | O33: =IFERROR(__xludf.DUMMYFUNCTION("""COMPUTED_VALUE"""),23.58) -> 23.58 | Q33: =IFERROR(__xludf.DUMMYFUNCTION("""COMPUTED_VALUE"""),44244.66666666667) -> 44244.667 | R33: =IFERROR(__xludf.DUMMYFUNCTION("""COMPUTED_VALUE"""),128.46) -> 128.46
B34: =IFERROR(__xludf.DUMMYFUNCTION("""COMPUTED_VALUE"""),44245.66666666667) -> 44245.667 | C34: =IFERROR(__xludf.DUMMYFUNCTION("""COMPUTED_VALUE"""),46.34) -> 46.34 | E34: =IFERROR(__xludf.DUMMYFUNCTION("""COMPUTED_VALUE"""),45544.66666666667) -> 45544.667 | F34: =IFERROR(__xludf.DUMMYFUNCTION("""COMPUTED_VALUE"""),1.22) -> 1.22 | H34: =IFERROR(__xludf.DUMMYFUNCTION("""COMPUTED_VALUE"""),45295.66666666667) -> 45295.667 | I34: =IFERROR(__xludf.DUMMYFUNCTION("""COMPUTED_VALUE"""),5.93) -> 5.93 | K34: =IFERROR(__xludf.DUMMYFUNCTION("""COMPUTED_VALUE"""),44243.6875) -> 44243.688 | L34: =IFERROR(__xludf.DUMMYFUNCTION("""COMPUTED_VALUE"""),39.48) -> 39.48 | N34: =IFERROR(__xludf.DUMMYFUNCTION("""COMPUTED_VALUE"""),44245.66666666667) -> 44245.667 | O34: =IFERROR(__xludf.DUMMYFUNCTION("""COMPUTED_VALUE"""),22.46) -> 22.46 | Q34: =IFERROR(__xludf.DUMMYFUNCTION("""COMPUTED_VALUE"""),44245.66666666667) -> 44245.667 | R34: =IFERROR(__xludf.DUMMYFUNCTION("""COMPUTED_VALUE"""),129.53) -> 129.53
B35: =IFERROR(__xludf.DUMMYFUNCTION("""COMPUTED_VALUE"""),44246.66666666667) -> 44246.667 | C35: =IFERROR(__xludf.DUMMYFUNCTION("""COMPUTED_VALUE"""),45.68) -> 45.68 | E35: =IFERROR(__xludf.DUMMYFUNCTION("""COMPUTED_VALUE"""),45545.66666666667) -> 45545.667 | F35: =IFERROR(__xludf.DUMMYFUNCTION("""COMPUTED_VALUE"""),1.2) -> 1.2 | H35: =IFERROR(__xludf.DUMMYFUNCTION("""COMPUTED_VALUE"""),45296.66666666667) -> 45296.667 | I35: =IFERROR(__xludf.DUMMYFUNCTION("""COMPUTED_VALUE"""),6.48) -> 6.48 | K35: =IFERROR(__xludf.DUMMYFUNCTION("""COMPUTED_VALUE"""),44244.6875) -> 44244.688 | L35: =IFERROR(__xludf.DUMMYFUNCTION("""COMPUTED_VALUE"""),38.92) -> 38.92 | N35: =IFERROR(__xludf.DUMMYFUNCTION("""COMPUTED_VALUE"""),44246.66666666667) -> 44246.667 | O35: =IFERROR(__xludf.DUMMYFUNCTION("""COMPUTED_VALUE"""),22.87) -> 22.87 | Q35: =IFERROR(__xludf.DUMMYFUNCTION("""COMPUTED_VALUE"""),44246.66666666667) -> 44246.667 | R35: =IFERROR(__xludf.DUMMYFUNCTION("""COMPUTED_VALUE"""),127.12) -> 127.12
B36: =IFERROR(__xludf.DUMMYFUNCTION("""COMPUTED_VALUE"""),44249.66666666667) -> 44249.667 | C36: =IFERROR(__xludf.DUMMYFUNCTION("""COMPUTED_VALUE"""),45.43) -> 45.43 | E36: =IFERROR(__xludf.DUMMYFUNCTION("""COMPUTED_VALUE"""),45546.66666666667) -> 45546.667 | F36: =IFERROR(__xludf.DUMMYFUNCTION("""COMPUTED_VALUE"""),1.2) -> 1.2 | H36: =IFERROR(__xludf.DUMMYFUNCTION("""COMPUTED_VALUE"""),45299.66666666667) -> 45299.667 | I36: =IFERROR(__xludf.DUMMYFUNCTION("""COMPUTED_VALUE"""),6.23) -> 6.23 | K36: =IFERROR(__xludf.DUMMYFUNCTION("""COMPUTED_VALUE"""),44245.6875) -> 44245.688 | L36: =IFERROR(__xludf.DUMMYFUNCTION("""COMPUTED_VALUE"""),37.49) -> 37.49 | N36: =IFERROR(__xludf.DUMMYFUNCTION("""COMPUTED_VALUE"""),44249.66666666667) -> 44249.667 | O36: =IFERROR(__xludf.DUMMYFUNCTION("""COMPUTED_VALUE"""),23.63) -> 23.63 | Q36: =IFERROR(__xludf.DUMMYFUNCTION("""COMPUTED_VALUE"""),44249.66666666667) -> 44249.667 | R36: =IFERROR(__xludf.DUMMYFUNCTION("""COMPUTED_VALUE"""),126.58) -> 126.58
B37: =IFERROR(__xludf.DUMMYFUNCTION("""COMPUTED_VALUE"""),44250.66666666667) -> 44250.667 | C37: =IFERROR(__xludf.DUMMYFUNCTION("""COMPUTED_VALUE"""),45.51) -> 45.51 | E37: =IFERROR(__xludf.DUMMYFUNCTION("""COMPUTED_VALUE"""),45547.66666666667) -> 45547.667 | F37: =IFERROR(__xludf.DUMMYFUNCTION("""COMPUTED_VALUE"""),1.22) -> 1.22 | H37: =IFERROR(__xludf.DUMMYFUNCTION("""COMPUTED_VALUE"""),45300.66666666667) -> 45300.667 | I37: =IFERROR(__xludf.DUMMYFUNCTION("""COMPUTED_VALUE"""),6.66) -> 6.66 | K37: =IFERROR(__xludf.DUMMYFUNCTION("""COMPUTED_VALUE"""),44246.6875) -> 44246.688 | L37: =IFERROR(__xludf.DUMMYFUNCTION("""COMPUTED_VALUE"""),38.19) -> 38.19 | N37: =IFERROR(__xludf.DUMMYFUNCTION("""COMPUTED_VALUE"""),44250.66666666667) -> 44250.667 | O37: =IFERROR(__xludf.DUMMYFUNCTION("""COMPUTED_VALUE"""),24.23) -> 24.23 | Q37: =IFERROR(__xludf.DUMMYFUNCTION("""COMPUTED_VALUE"""),44250.66666666667) -> 44250.667 | R37: =IFERROR(__xludf.DUMMYFUNCTION("""COMPUTED_VALUE"""),127.52) -> 127.52
B38: =IFERROR(__xludf.DUMMYFUNCTION("""COMPUTED_VALUE"""),44251.66666666667) -> 44251.667 | C38: =IFERROR(__xludf.DUMMYFUNCTION("""COMPUTED_VALUE"""),45.74) -> 45.74 | E38: =IFERROR(__xludf.DUMMYFUNCTION("""COMPUTED_VALUE"""),45548.66666666667) -> 45548.667 | F38: =IFERROR(__xludf.DUMMYFUNCTION("""COMPUTED_VALUE"""),1.26) -> 1.26 | H38: =IFERROR(__xludf.DUMMYFUNCTION("""COMPUTED_VALUE"""),45301.66666666667) -> 45301.667 | I38: =IFERROR(__xludf.DUMMYFUNCTION("""COMPUTED_VALUE"""),7.79) -> 7.79 | K38: =IFERROR(__xludf.DUMMYFUNCTION("""COMPUTED_VALUE"""),44249.6875) -> 44249.688 | L38: =IFERROR(__xludf.DUMMYFUNCTION("""COMPUTED_VALUE"""),38.42) -> 38.42 | N38: =IFERROR(__xludf.DUMMYFUNCTION("""COMPUTED_VALUE"""),44251.66666666667) -> 44251.667 | O38: =IFERROR(__xludf.DUMMYFUNCTION("""COMPUTED_VALUE"""),25.3) -> 25.3 | Q38: =IFERROR(__xludf.DUMMYFUNCTION("""COMPUTED_VALUE"""),44251.66666666667) -> 44251.667 | R38: =IFERROR(__xludf.DUMMYFUNCTION("""COMPUTED_VALUE"""),127.66) -> 127.66
B39: =IFERROR(__xludf.DUMMYFUNCTION("""COMPUTED_VALUE"""),44252.66666666667) -> 44252.667 | C39: =IFERROR(__xludf.DUMMYFUNCTION("""COMPUTED_VALUE"""),45.52) -> 45.52 | E39: =IFERROR(__xludf.DUMMYFUNCTION("""COMPUTED_VALUE"""),45551.66666666667) -> 45551.667 | F39: =IFERROR(__xludf.DUMMYFUNCTION("""COMPUTED_VALUE"""),1.31) -> 1.31 | H39: =IFERROR(__xludf.DUMMYFUNCTION("""COMPUTED_VALUE"""),45302.66666666667) -> 45302.667 | I39: =IFERROR(__xludf.DUMMYFUNCTION("""COMPUTED_VALUE"""),7.9) -> 7.9 | K39: =IFERROR(__xludf.DUMMYFUNCTION("""COMPUTED_VALUE"""),44250.6875) -> 44250.688 | L39: =IFERROR(__xludf.DUMMYFUNCTION("""COMPUTED_VALUE"""),39.22) -> 39.22 | N39: =IFERROR(__xludf.DUMMYFUNCTION("""COMPUTED_VALUE"""),44252.66666666667) -> 44252.667 | O39: =IFERROR(__xludf.DUMMYFUNCTION("""COMPUTED_VALUE"""),25.59) -> 25.59 | Q39: =IFERROR(__xludf.DUMMYFUNCTION("""COMPUTED_VALUE"""),44252.66666666667) -> 44252.667 | R39: =IFERROR(__xludf.DUMMYFUNCTION("""COMPUTED_VALUE"""),126.58) -> 126.58
B40: =IFERROR(__xludf.DUMMYFUNCTION("""COMPUTED_VALUE"""),44253.66666666667) -> 44253.667 | C40: =IFERROR(__xludf.DUMMYFUNCTION("""COMPUTED_VALUE"""),44.87) -> 44.87 | E40: =IFERROR(__xludf.DUMMYFUNCTION("""COMPUTED_VALUE"""),45552.66666666667) -> 45552.667 | F40: =IFERROR(__xludf.DUMMYFUNCTION("""COMPUTED_VALUE"""),1.34) -> 1.34 | H40: =IFERROR(__xludf.DUMMYFUNCTION("""COMPUTED_VALUE"""),45303.66666666667) -> 45303.667 | I40: =IFERROR(__xludf.DUMMYFUNCTION("""COMPUTED_VALUE"""),8.0) -> 8 | K40: =IFERROR(__xludf.DUMMYFUNCTION("""COMPUTED_VALUE"""),44251.6875) -> 44251.688 | L40: =IFERROR(__xludf.DUMMYFUNCTION("""COMPUTED_VALUE"""),39.34) -> 39.34 | N40: =IFERROR(__xludf.DUMMYFUNCTION("""COMPUTED_VALUE"""),44253.66666666667) -> 44253.667 | O40: =IFERROR(__xludf.DUMMYFUNCTION("""COMPUTED_VALUE"""),24.41) -> 24.41 | Q40: =IFERROR(__xludf.DUMMYFUNCTION("""COMPUTED_VALUE"""),44253.66666666667) -> 44253.667 | R40: =IFERROR(__xludf.DUMMYFUNCTION("""COMPUTED_VALUE"""),123.53) -> 123.53
...

Sheet Maths
A1: Cisco Daily returns | B1: NVIDIA Daily returns | C1: RR Daily returns | D1: Lloydes Daily returns | E1: BP Daily returns | F1: PG 500 Daily Returns | J1: Stock/EFT | K1: Average | L1: Standard Deviation | P1: =J2 -> Cisco | Q1: =O3 -> NVIDAI | R1: =O4 -> RR | S1: =O5 -> Lloydes | T1: =O6 -> BP | U1: =O7 -> PG
A2: =(('Historical Data'!C4)-('Historical Data'!C3))/('Historical Data'!C3) -> 0.00045495905 | B2: =(('Historical Data'!F4)-('Historical Data'!F3))/('Historical Data'!F3) -> 0 | C2: =(('Historical Data'!I4)-('Historical Data'!I3))/('Historical Data'!I3) -> 0.078095238 | D2: =(('Historical Data'!L4)-('Historical Data'!L3))/('Historical Data'!L3) -> 0.010619977 | E2: =(('Historical Data'!O4)-('Historical Data'!O3))/('Historical Data'!O3) -> 0.074411906 | F2: =(('Historical Data'!R4)-('Historical Data'!R3))/('Historical Data'!R3) -> 0.00638514 | J2: Cisco | K2: =AVERAGE(A:A) -> 0.00056585805 | L2: =STDEV(A:A) -> 0.014657906 | O2: =J2 -> Cisco | P2: =_xlfn.VAR.S(A2:A2000) -> 0.00021485421 | Q2: =_xlfn.COVARIANCE.S(A2:A2000,B2:B2000) -> 8.3691394e-05 | R2: =_xlfn.COVARIANCE.S(A2:A2000,C2:C2000) -> 5.0080623e-05 | S2: =_xlfn.COVARIANCE.S(A2:A2000,D2:D2000) -> 5.7581698e-06 | T2: =_xlfn.COVARIANCE.S(A2:A2000,E2:E2000) -> 6.2818877e-05 | U2: =_xlfn.COVARIANCE.S(A2:A2000,F2:F2000) -> 5.2966798e-05
A3: =(('Historical Data'!C5)-('Historical Data'!C4))/('Historical Data'!C4) -> 0.0095497954 | B3: =(('Historical Data'!F5)-('Historical Data'!F4))/('Historical Data'!F4) -> 0.041666667 | C3: =(('Historical Data'!I5)-('Historical Data'!I4))/('Historical Data'!I4) -> -0.019434629 | D3: =(('Historical Data'!L5)-('Historical Data'!L4))/('Historical Data'!L4) -> 0.055381994 | E3: =(('Historical Data'!O5)-('Historical Data'!O4))/('Historical Data'!O4) -> 0.046023235 | F3: =(('Historical Data'!R5)-('Historical Data'!R4))/('Historical Data'!R4) -> 0.010526316 | J3: NVIDAI | K3: =AVERAGE(B:B) -> 0.0059292059 | L3: =STDEV(B:B) -> 0.10183098 | O3: =J3 -> NVIDAI | P3: =_xlfn.COVARIANCE.S(A2:A2000,B2:B2000) -> 8.3691394e-05 | Q3: =_xlfn.VAR.S(B2:B2000) -> 0.010369548 | R3: =_xlfn.COVARIANCE.S(B2:B2000,C2:C2000) -> -1.7798516e-05 | S3: =_xlfn.COVARIANCE.S(B2:B2000,D2:D2000) -> 0.00011331887 | T3: =_xlfn.COVARIANCE.S(B2:B2000,E2:E2000) -> 9.4898474e-05 | U3: =_xlfn.COVARIANCE.S(B2:B2000,F2:F2000) -> -7.1007765e-05
A4: =(('Historical Data'!C6)-('Historical Data'!C5))/('Historical Data'!C5) -> 0.012612613 | B4: =(('Historical Data'!F6)-('Historical Data'!F5))/('Historical Data'!F5) -> 0.01 | C4: =(('Historical Data'!I6)-('Historical Data'!I5))/('Historical Data'!I5) -> -0.061261261 | D4: =(('Historical Data'!L6)-('Historical Data'!L5))/('Historical Data'!L5) -> -0.0072658773 | E4: =(('Historical Data'!O6)-('Historical Data'!O5))/('Historical Data'!O5) -> 0.021358394 | F4: =(('Historical Data'!R6)-('Historical Data'!R5))/('Historical Data'!R5) -> -0.0093464612 | J4: RR | K4: =AVERAGE(C:C) -> 0.0056615594 | L4: =STDEV(C:C) -> 0.10748995 | O4: =J4 -> RR | P4: =_xlfn.COVARIANCE.S(A2:A2000,C2:C2000) -> 5.0080623e-05 | Q4: =_xlfn.COVARIANCE.S(C2:C2000,B2:B2000) -> -1.7798516e-05 | R4: =_xlfn.VAR.S(C2:C2000) -> 0.01155409 | S4: =_xlfn.COVARIANCE.S(C2:C2000,D2:D2000) -> 7.5546274e-05 | T4: =_xlfn.COVARIANCE.S(C2:C2000,E2:E2000) -> 0.0001452138 | U4: =_xlfn.COVARIANCE.S(C2:C2000,F2:F2000) -> 1.7000329e-05
A5: =(('Historical Data'!C7)-('Historical Data'!C6))/('Historical Data'!C6) -> 0.0022241993 | B5: =(('Historical Data'!F7)-('Historical Data'!F6))/('Historical Data'!F6) -> 0.0099009901 | C5: =(('Historical Data'!I7)-('Historical Data'!I6))/('Historical Data'!I6) -> -0.11324376 | D5: =(('Historical Data'!L7)-('Historical Data'!L6))/('Historical Data'!L6) -> -0.001626457 | E5: =(('Historical Data'!O7)-('Historical Data'!O6))/('Historical Data'!O6) -> 0.020493517 | F5: =(('Historical Data'!R7)-('Historical Data'!R6))/('Historical Data'!R6) -> -0.00043212099 | J5: Lloydes | K5: =AVERAGE(D:D) -> 0.00099335792 | L5: =stdev(D:D) -> 0.016927524 | O5: =J5 -> Lloydes | P5: =_xlfn.COVARIANCE.S(A2:A2000,D2:D2000) -> 5.7581698e-06 | Q5: =_xlfn.COVARIANCE.S(D2:D2000,B2:B2000) -> 0.00011331887 | R5: =_xlfn.COVARIANCE.S(C2:C2000,D2:D2000) -> 7.5546274e-05 | S5: =_xlfn.VAR.S(D2:D2000) -> 0.00028654107 | T5: =_xlfn.COVARIANCE.S(D2:D2000,E2:E2000) -> 1.7390007e-05 | U5: =_xlfn.COVARIANCE.S(D2:D2000,F2:F2000) -> 8.4212594e-06
A6: =(('Historical Data'!C8)-('Historical Data'!C7))/('Historical Data'!C7) -> 0.0066577896 | B6: =(('Historical Data'!F8)-('Historical Data'!F7))/('Historical Data'!F7) -> 0.0098039216 | C6: =(('Historical Data'!I8)-('Historical Data'!I7))/('Historical Data'!I7) -> -0.012987013 | D6: =(('Historical Data'!L8)-('Historical Data'!L7))/('Historical Data'!L7) -> -0.017920174 | E6: =(('Historical Data'!O8)-('Historical Data'!O7))/('Historical Data'!O7) -> -0.00081967213 | F6: =(('Historical Data'!R8)-('Historical Data'!R7))/('Historical Data'!R7) -> -0.0067728222 | J6: BP | K6: =AVERAGE(E:E) -> 0.00066752957 | L6: =stdev(E:E) -> 0.018606047 | O6: =J6 -> BP | P6: =_xlfn.COVARIANCE.S(A2:A2000,E2:E2000) -> 6.2818877e-05 | Q6: =_xlfn.COVARIANCE.S(B2:B2000,E2:E2000) -> 9.4898474e-05 | R6: =_xlfn.COVARIANCE.S(C2:C2000,E2:E2000) -> 0.0001452138 | S6: =_xlfn.COVARIANCE.S(D2:D2000,E2:E2000) -> 1.7390007e-05 | T6: =_xlfn.VAR.S(E2:E2000) -> 0.00034618499 | U6: =_xlfn.COVARIANCE.S(E2:E2000,F2:F2000) -> 1.2350217e-05
A7: =(('Historical Data'!C9)-('Historical Data'!C8))/('Historical Data'!C8) -> 0.0094797178 | B7: =(('Historical Data'!F9)-('Historical Data'!F8))/('Historical Data'!F8) -> -0.0097087379 | C7: =(('Historical Data'!I9)-('Historical Data'!I8))/('Historical Data'!I8) -> 0.021929825 | D7: =(('Historical Data'!L9)-('Historical Data'!L8))/('Historical Data'!L8) -> 0.015758916 | E7: =(('Historical Data'!O9)-('Historical Data'!O8))/('Historical Data'!O8) -> 0.025840853 | F7: =(('Historical Data'!R9)-('Historical Data'!R8))/('Historical Data'!R8) -> -0.0058034095 | J7: PG | K7: =AVERAGE(F:F) -> 0.00027299464 | L7: =STDEV(F:F) -> 0.010728947 | O7: =J7 -> PG | P7: =_xlfn.COVARIANCE.S(A2:A2000,F2:F2000) -> 5.2966798e-05 | Q7: =_xlfn.COVARIANCE.S(B2:B2000,F2:F2000) -> -7.1007765e-05 | R7: =_xlfn.COVARIANCE.S(C2:C2000,F2:F2000) -> 1.7000329e-05 | S7: =_xlfn.COVARIANCE.S(D2:D2000,F2:F2000) -> 8.4212594e-06 | T7: =_xlfn.COVARIANCE.S(E2:E2000,F2:F2000) -> 1.2350217e-05 | U7: =_xlfn.VAR.S(F2:F2000) -> 0.0001151103
A8: =(('Historical Data'!C10)-('Historical Data'!C9))/('Historical Data'!C9) -> -0.0093906967 | B8: =(('Historical Data'!F10)-('Historical Data'!F9))/('Historical Data'!F9) -> -0.029411765 | C8: =(('Historical Data'!I10)-('Historical Data'!I9))/('Historical Data'!I9) -> -0.10085837 | D8: =(('Historical Data'!L10)-('Historical Data'!L9))/('Historical Data'!L9) -> -0.013609145 | E8: =(('Historical Data'!O10)-('Historical Data'!O9))/('Historical Data'!O9) -> -0.0091963215 | F8: =(('Historical Data'!R10)-('Historical Data'!R9))/('Historical Data'!R9) -> 0.0015322875
A9: =(('Historical Data'!C11)-('Historical Data'!C10))/('Historical Data'!C10) -> -0.0046296296 | B9: =(('Historical Data'!F11)-('Historical Data'!F10))/('Historical Data'!F10) -> 0 | C9: =(('Historical Data'!I11)-('Historical Data'!I10))/('Historical Data'!I10) -> 0.019093079 | D9: =(('Historical Data'!L11)-('Historical Data'!L10))/('Historical Data'!L10) -> 0.0060706402 | E9: =(('Historical Data'!O11)-('Historical Data'!O10))/('Historical Data'!O10) -> 0.027845036 | F9: =(('Historical Data'!R11)-('Historical Data'!R10))/('Historical Data'!R10) -> -0.010636748
A10: =(('Historical Data'!C12)-('Historical Data'!C11))/('Historical Data'!C11) -> 0.0062015504 | B10: =(('Historical Data'!F12)-('Historical Data'!F11))/('Historical Data'!F11) -> 0.02020202 | C10: =(('Historical Data'!I12)-('Historical Data'!I11))/('Historical Data'!I11) -> 0.049180328 | D10: =(('Historical Data'!L12)-('Historical Data'!L11))/('Historical Data'!L11) -> -0.014262205 | E10: =(('Historical Data'!O12)-('Historical Data'!O11))/('Historical Data'!O11) -> -0.047506871 | F10: =(('Historical Data'!R12)-('Historical Data'!R11))/('Historical Data'!R11) -> -0.0075110457 | J10: Covariance Matrix | K10: =_xlfn.COVARIANCE.S(K2:K7,L2:L7) -> 0.00012363129
A11: =(('Historical Data'!C13)-('Historical Data'!C12))/('Historical Data'!C12) -> -0.0052828527 | B11: =(('Historical Data'!F13)-('Historical Data'!F12))/('Historical Data'!F12) -> 0 | C11: =(('Historical Data'!I13)-('Historical Data'!I12))/('Historical Data'!I12) -> 0.12276786 | D11: =(('Historical Data'!L13)-('Historical Data'!L12))/('Historical Data'!L12) -> 0.0063995548 | E11: =(('Historical Data'!O13)-('Historical Data'!O12))/('Historical Data'!O12) -> 0.016075845 | F11: =(('Historical Data'!R13)-('Historical Data'!R12))/('Historical Data'!R12) -> -0.0087550082
A12: =(('Historical Data'!C14)-('Historical Data'!C13))/('Historical Data'!C13) -> 0.0033193184 | B12: =(('Historical Data'!F14)-('Historical Data'!F13))/('Historical Data'!F13) -> 0.12871287 | C12: =(('Historical Data'!I14)-('Historical Data'!I13))/('Historical Data'!I13) -> -0.011928429 | D12: =(('Historical Data'!L14)-('Historical Data'!L13))/('Historical Data'!L13) -> -0.0047000276 | E12: =(('Historical Data'!O14)-('Historical Data'!O13))/('Historical Data'!O13) -> 0.0064908722 | F12: =(('Historical Data'!R14)-('Historical Data'!R13))/('Historical Data'!R13) -> -0.0125
A13: =(('Historical Data'!C15)-('Historical Data'!C14))/('Historical Data'!C14) -> -0.0050727834 | B13: =(('Historical Data'!F15)-('Historical Data'!F14))/('Historical Data'!F14) -> 0.0087719298 | C13: =(('Historical Data'!I15)-('Historical Data'!I14))/('Historical Data'!I14) -> 0.024144869 | D13: =(('Historical Data'!L15)-('Historical Data'!L14))/('Historical Data'!L14) -> -0.0061111111 | E13: =(('Historical Data'!O15)-('Historical Data'!O14))/('Historical Data'!O14) -> -0.031841999 | F13: =(('Historical Data'!R15)-('Historical Data'!R14))/('Historical Data'!R14) -> -0.006973395
A14: =(('Historical Data'!C16)-('Historical Data'!C15))/('Historical Data'!C15) -> -0.0075371315 | B14: =(('Historical Data'!F16)-('Historical Data'!F15))/('Historical Data'!F15) -> -0.13043478 | C14: =(('Historical Data'!I16)-('Historical Data'!I15))/('Historical Data'!I15) -> 0.0039292731 | D14: =(('Historical Data'!L16)-('Historical Data'!L15))/('Historical Data'!L15) -> -0.012856344 | E14: =(('Historical Data'!O16)-('Historical Data'!O15))/('Historical Data'!O15) -> -0.006244796 | F14: =(('Historical Data'!R16)-('Historical Data'!R15))/('Historical Data'!R15) -> -0.0077093352
A15: =(('Historical Data'!C17)-('Historical Data'!C16))/('Historical Data'!C16) -> 0.0058074604 | B15: =(('Historical Data'!F17)-('Historical Data'!F16))/('Historical Data'!F16) -> -0.03 | C15: =(('Historical Data'!I17)-('Historical Data'!I16))/('Historical Data'!I16) -> -0.019569472 | D15: =(('Historical Data'!L17)-('Historical Data'!L16))/('Historical Data'!L16) -> -0.015571914 | E15: =(('Historical Data'!O17)-('Historical Data'!O16))/('Historical Data'!O16) -> -0.033514872 | F15: =(('Historical Data'!R17)-('Historical Data'!R16))/('Historical Data'!R16) -> 0.017230769
A16: =(('Historical Data'!C18)-('Historical Data'!C17))/('Historical Data'!C17) -> 0.005107706 | B16: =(('Historical Data'!F18)-('Historical Data'!F17))/('Historical Data'!F17) -> -0.030927835 | C16: =(('Historical Data'!I18)-('Historical Data'!I17))/('Historical Data'!I17) -> -0.005988024 | D16: =(('Historical Data'!L18)-('Historical Data'!L17))/('Historical Data'!L17) -> -0.026747196 | E16: =(('Historical Data'!O18)-('Historical Data'!O17))/('Historical Data'!O17) -> -0.0017338535 | F16: =(('Historical Data'!R18)-('Historical Data'!R17))/('Historical Data'!R17) -> 0.0064277072
A17: =(('Historical Data'!C19)-('Historical Data'!C18))/('Historical Data'!C18) -> 0.0097216085 | B17: =(('Historical Data'!F19)-('Historical Data'!F18))/('Historical Data'!F18) -> 0.13829787 | C17: =(('Historical Data'!I19)-('Historical Data'!I18))/('Historical Data'!I18) -> -0.040160643 | D17: =(('Historical Data'!L19)-('Historical Data'!L18))/('Historical Data'!L18) -> 0.016843972 | E17: =(('Historical Data'!O19)-('Historical Data'!O18))/('Historical Data'!O18) -> -0.013026487 | F17: =(('Historical Data'!R19)-('Historical Data'!R18))/('Historical Data'!R18) -> -0.035389586
A18: =(('Historical Data'!C20)-('Historical Data'!C19))/('Historical Data'!C19) -> -0.0078774617 | B18: =(('Historical Data'!F20)-('Historical Data'!F19))/('Historical Data'!F19) -> 0.093457944 | C18: =(('Historical Data'!I20)-('Historical Data'!I19))/('Historical Data'!I19) -> 0.0041841004 | D18: =(('Historical Data'!L20)-('Historical Data'!L19))/('Historical Data'!L19) -> -0.03371113 | E18: =(('Historical Data'!O20)-('Historical Data'!O19))/('Historical Data'!O19) -> 0.0057193137 | F18: =(('Historical Data'!R20)-('Historical Data'!R19))/('Historical Data'!R19) -> 0.015422963
A19: =(('Historical Data'!C21)-('Historical Data'!C20))/('Historical Data'!C20) -> -0.016762241 | B19: =(('Historical Data'!F21)-('Historical Data'!F20))/('Historical Data'!F20) -> 0 | C19: =(('Historical Data'!I21)-('Historical Data'!I20))/('Historical Data'!I20) -> -0.014583333 | D19: =(('Historical Data'!L21)-('Historical Data'!L20))/('Historical Data'!L20) -> 0.0066165414 | E19: =(('Historical Data'!O21)-('Historical Data'!O20))/('Historical Data'!O20) -> -0.0279965 | F19: =(('Historical Data'!R21)-('Historical Data'!R20))/('Historical Data'!R20) -> -0.016492789
A20: =(('Historical Data'!C22)-('Historical Data'!C21))/('Historical Data'!C21) -> 0.018393899 | B20: =(('Historical Data'!F22)-('Historical Data'!F21))/('Historical Data'!F21) -> 0.0085470085 | C20: =(('Historical Data'!I22)-('Historical Data'!I21))/('Historical Data'!I21) -> -0.0042283298 | D20: =(('Historical Data'!L22)-('Historical Data'!L21))/('Historical Data'!L21) -> -0.014042426 | E20: =(('Historical Data'!O22)-('Historical Data'!O21))/('Historical Data'!O21) -> -0.000450045 | F20: =(('Historical Data'!R22)-('Historical Data'!R21))/('Historical Data'!R21) -> 0.0059277747
A21: =(('Historical Data'!C23)-('Historical Data'!C22))/('Historical Data'!C22) -> 0.0094713656 | B21: =(('Historical Data'!F23)-('Historical Data'!F22))/('Historical Data'!F22) -> 0 | C21: =(('Historical Data'!I23)-('Historical Data'!I22))/('Historical Data'!I22) -> 0.01910828 | D21: =(('Historical Data'!L23)-('Historical Data'!L22))/('Historical Data'!L22) -> 0.016060606 | E21: =(('Historical Data'!O23)-('Historical Data'!O22))/('Historical Data'!O22) -> -0.065736155 | F21: =(('Historical Data'!R23)-('Historical Data'!R22))/('Historical Data'!R22) -> -0.0013956734
A22: =(('Historical Data'!C24)-('Historical Data'!C23))/('Historical Data'!C23) -> -0.0013091861 | B22: =(('Historical Data'!F24)-('Historical Data'!F23))/('Historical Data'!F23) -> 0.050847458 | C22: =(('Historical Data'!I24)-('Historical Data'!I23))/('Historical Data'!I23) -> 0.05625 | D22: =(('Historical Data'!L24)-('Historical Data'!L23))/('Historical Data'!L23) -> 0.013719058 | E22: =(('Historical Data'!O24)-('Historical Data'!O23))/('Historical Data'!O23) -> 0.025060241 | F22: =(('Historical Data'!R24)-('Historical Data'!R23))/('Historical Data'!R23) -> 0.0012423325
... A397: =(('Historical Data'!C399)-('Historical Data'!C398))/('Historical Data'!C398) -> -0.0019836897 | B397: =(('Historical Data'!F399)-('Historical Data'!F398))/('Historical Data'!F398) -> -1 | C397: =(('Historical Data'!I399)-('Historical Data'!I398))/('Historical Data'!I398) -> -0.042780749 | D397: =(('Historical Data'!L399)-('Historical Data'!L398))/('Historical Data'!L398) -> 0.018455998 | E397: =(('Historical Data'!O399)-('Historical Data'!O398))/('Historical Data'!O398) -> -0.011232131 | F397: =(('Historical Data'!R399)-('Historical Data'!R398))/('Historical Data'!R398) -> 0.028723634
A398: =(('Historical Data'!C400)-('Historical Data'!C399))/('Historical Data'!C399) -> -0.00795053 | C398: =(('Historical Data'!I400)-('Historical Data'!I399))/('Historical Data'!I399) -> -0.0055865922 | D398: =(('Historical Data'!L400)-('Historical Data'!L399))/('Historical Data'!L399) -> -0.004198895 | E398: =(('Historical Data'!O400)-('Historical Data'!O399))/('Historical Data'!O399) -> 0.010671256 | F398: =(('Historical Data'!R400)-('Historical Data'!R399))/('Historical Data'!R399) -> -0.0066480056
A399: =(('Historical Data'!C401)-('Historical Data'!C400))/('Historical Data'!C400) -> 0.017586821 | C399: =(('Historical Data'!I401)-('Historical Data'!I400))/('Historical Data'!I400) -> 0.08988764 | D399: =(('Historical Data'!L401)-('Historical Data'!L400))/('Historical Data'!L400) -> 0.0075454949 | E399: =(('Historical Data'!O401)-('Historical Data'!O400))/('Historical Data'!O400) -> 0.011239782 | F399: =(('Historical Data'!R401)-('Historical Data'!R400))/('Historical Data'!R400) -> 0.020641071
A400: =(('Historical Data'!C402)-('Historical Data'!C401))/('Historical Data'!C401) -> -0.0072194268 | C400: =(('Historical Data'!I402)-('Historical Data'!I401))/('Historical Data'!I401) -> -0.020618557 | D400: =(('Historical Data'!L402)-('Historical Data'!L401))/('Historical Data'!L401) -> 0.0094713656 | E400: =(('Historical Data'!O402)-('Historical Data'!O401))/('Historical Data'!O401) -> -0.011451667 | F400: =(('Historical Data'!R402)-('Historical Data'!R401))/('Historical Data'!R401) -> -0.0015875207
A401: =(('Historical Data'!C403)-('Historical Data'!C402))/('Historical Data'!C402) -> -0.0081533715 | C401: =(('Historical Data'!I403)-('Historical Data'!I402))/('Historical Data'!I402) -> 0.084210526 | D401: =(('Historical Data'!L403)-('Historical Data'!L402))/('Historical Data'!L402) -> -0.015928431 | E401: =(('Historical Data'!O403)-('Historical Data'!O402))/('Historical Data'!O402) -> 0.010562181 | F401: =(('Historical Data'!R403)-('Historical Data'!R402))/('Historical Data'!R402) -> 0.00048392672
A402: =(('Historical Data'!C404)-('Historical Data'!C403))/('Historical Data'!C403) -> 0.00022217285 | C402: =(('Historical Data'!I404)-('Historical Data'!I403))/('Historical Data'!I403) -> -0.058252427 | D402: =(('Historical Data'!L404)-('Historical Data'!L403))/('Historical Data'!L403) -> -0.0042128603 | E402: =(('Historical Data'!O404)-('Historical Data'!O403))/('Historical Data'!O403) -> 0.016857721 | F402: =(('Historical Data'!R404)-('Historical Data'!R403))/('Historical Data'!R403) -> 0.0038004422
A403: =(('Historical Data'!C405)-('Historical Data'!C404))/('Historical Data'!C404) -> -0.002221235 | C403: =(('Historical Data'!I405)-('Historical Data'!I404))/('Historical Data'!I404) -> 0.0051546392 | D403: =(('Historical Data'!L405)-('Historical Data'!L404))/('Historical Data'!L404) -> 0.0073480294 | E403: =(('Historical Data'!O405)-('Historical Data'!O404))/('Historical Data'!O404) -> 0.013594164 | F403: =(('Historical Data'!R405)-('Historical Data'!R404))/('Historical Data'!R404) -> -0.0023404695
A404: =(('Historical Data'!C406)-('Historical Data'!C405))/('Historical Data'!C405) -> 0.024487979 | C404: =(('Historical Data'!I406)-('Historical Data'!I405))/('Historical Data'!I405) -> 0 | D404: =(('Historical Data'!L406)-('Historical Data'!L405))/('Historical Data'!L405) -> -0.0053050398 | E404: =(('Historical Data'!O406)-('Historical Data'!O405))/('Historical Data'!O405) -> 0.0075237161 | F404: =(('Historical Data'!R406)-('Historical Data'!R405))/('Historical Data'!R405) -> 0.0094528393
A405: =(('Historical Data'!C407)-('Historical Data'!C406))/('Historical Data'!C406) -> -0.0026075619 | C405: =(('Historical Data'!I407)-('Historical Data'!I406))/('Historical Data'!I406) -> 0.030769231 | D405: =(('Historical Data'!L407)-('Historical Data'!L406))/('Historical Data'!L406) -> 0.010444444 | E405: =(('Historical Data'!O407)-('Historical Data'!O406))/('Historical Data'!O406) -> 0.02012987 | F405: =(('Historical Data'!R407)-('Historical Data'!R406))/('Historical Data'!R406) -> -0.0071086808
A406: =(('Historical Data'!C408)-('Historical Data'!C407))/('Historical Data'!C407) -> 0.01546841 | C406: =(('Historical Data'!I408)-('Historical Data'!I407))/('Historical Data'!I407) -> -0.024875622 | D406: =(('Historical Data'!L408)-('Historical Data'!L407))/('Historical Data'!L407) -> 0.0030789532 | E406: =(('Historical Data'!O408)-('Historical Data'!O407))/('Historical Data'!O407) -> 0.0079567155 | F406: =(('Historical Data'!R408)-('Historical Data'!R407))/('Historical Data'!R407) -> 0.0097067328
A407: =(('Historical Data'!C409)-('Historical Data'!C408))/('Historical Data'!C408) -> -0.00042909247 | C407: =(('Historical Data'!I409)-('Historical Data'!I408))/('Historical Data'!I408) -> -0.051020408 | D407: =(('Historical Data'!L409)-('Historical Data'!L408))/('Historical Data'!L408) -> 0.0010962508 | E407: =(('Historical Data'!O409)-('Historical Data'!O408))/('Historical Data'!O408) -> -0.022418693 | F407: =(('Historical Data'!R409)-('Historical Data'!R408))/('Historical Data'!R408) -> 0.012886071
